<?xml version="1.0"?>
<robot name="dtw_robot" xmlns:xacro="http://ros.org/wiki/xacro">

    <xacro:macro name="wheel_macro" params="parent prefix xyz">
        <joint name="${prefix}_joint" type="continuous">
            <origin xyz="${xyz}" rpy="${radians(-90)} 0 0"/>
            <parent link="${parent}"/>
            <child link="${prefix}_link"/>
            <axis xyz="0 0 1" />
        </joint>
        <link name="${prefix}_link">
            <visual>
                <geometry>
                    <cylinder radius="0.05" length="0.02" />
                </geometry>
                <material name="red">
                    <color rgba="1.0 0.0 0.0 2.5"/>
                </material>
            </visual>
        </link>
    </xacro:macro>

    <link name="base_link"/>

    <joint name="body_joint" type="fixed">
        <parent link="base_link"/>
        <child link="body_link"/>
        <origin xyz="-0.07 0 0.07" rpy="0 0 0"/>
    </joint>
    <link name="body_link">
        <visual>
            <origin xyz="0 0 0" rpy="0 0 0"/>
            <geometry>
                <box size="0.24 0.18 0.06"/>
            </geometry>
            <material name="gray">
                <color rgba="0.5 0.5 0.5 2.5"/>
            </material>

        </visual>
    </link>

    <joint name="right_wheel_joint" type="continuous">
        <parent link="base_link"/>
        <child link="right_wheel_link"/>
        <axis xyz="0 0 1" />
        <origin xyz="0 -0.1 0.05" rpy="-1.57 0 0"/>
    </joint>
    <link name="right_wheel_link">
        <visual>
            <geometry>
                <cylinder radius="0.05" length="0.02" />
            </geometry>
            <material name="red"/>
        </visual>
    </link>
    
    <joint name="left_wheel_joint" type="continuous">
        <parent link="base_link"/>
        <child link="left_wheel_link"/>
        <axis xyz="0 0 1" />
        <origin xyz="0 0.1 0.05" rpy="-1.57 0 0"/>
    </joint>
    <link name="left_wheel_link">
        <visual>
            <geometry>
                <cylinder radius="0.05" length="0.02" />
            </geometry>
            <material name="red">
                <color rgba="1.0 0.0 0.0 2.5"/>
            </material>
        </visual>
    </link>


    <joint name="ball_joint" type="fixed">
        <parent link="base_link"/>
        <child link="ball_link"/>
        <origin xyz="-0.14 0 0.04" rpy="0 0 0"/>
    </joint>
    <link name="ball_link">
        <visual>
            <origin xyz="0 0 0" rpy="0 0 0"/>
            <geometry>
                <sphere radius="0.04"/>
            </geometry>
            <material name="gray">
                <color rgba="0.5 0.5 0.5 2.5"/>
            </material>
        </visual>
    </link>
</robot>
