<?xml version="1.0" ?>
<!-- =================================================================================== -->
<!-- |    This document was autogenerated by xacro from dtw_robot1_2.xacro             | -->
<!-- |    EDITING THIS FILE BY HAND IS NOT RECOMMENDED                                 | -->
<!-- =================================================================================== -->
<robot name="dtw_robot" xmlns:xacro="http://ros.org/wiki/xacro">
  <link name="base_link"/>
  <joint name="body_joint" type="fixed">
    <parent link="base_link"/>
    <child link="body_link"/>
    <origin rpy="0 0 0" xyz="-0.07 0 0.07"/>
  </joint>
  <link name="body_link">
    <visual>
      <origin rpy="0 0 0" xyz="0 0 0"/>
      <geometry>
        <box size="0.24 0.18 0.06"/>
      </geometry>
      <material name="gray">
        <color rgba="0.5 0.5 0.5 2.5"/>
      </material>
    </visual>
  </link>
  <joint name="right_wheel_joint" type="continuous">
    <parent link="base_link"/>
    <child link="right_wheel_link"/>
    <axis xyz="0 0 1"/>
    <origin rpy="-1.57 0 0" xyz="0 -0.1 0.05"/>
  </joint>
  <link name="right_wheel_link">
    <visual>
      <geometry>
        <cylinder length="0.02" radius="0.05"/>
      </geometry>
      <material name="red"/>
    </visual>
  </link>
  <joint name="left_wheel_joint" type="continuous">
    <parent link="base_link"/>
    <child link="left_wheel_link"/>
    <axis xyz="0 0 1"/>
    <origin rpy="-1.57 0 0" xyz="0 0.1 0.05"/>
  </joint>
  <link name="left_wheel_link">
    <visual>
      <geometry>
        <cylinder length="0.02" radius="0.05"/>
      </geometry>
      <material name="red">
        <color rgba="1.0 0.0 0.0 2.5"/>
      </material>
    </visual>
  </link>
  <joint name="ball_joint" type="fixed">
    <parent link="base_link"/>
    <child link="ball_link"/>
    <origin rpy="0 0 0" xyz="-0.14 0 0.04"/>
  </joint>
  <link name="ball_link">
    <visual>
      <origin rpy="0 0 0" xyz="0 0 0"/>
      <geometry>
        <sphere radius="0.04"/>
      </geometry>
      <material name="gray">
        <color rgba="0.5 0.5 0.5 2.5"/>
      </material>
    </visual>
  </link>
</robot>

